Workbook

Sheet Pay Application
A1: Application and Certificate for Payment | D1: Not an AIA document · Print: fits one page
A2: Progress billing summary. Lines 4 to 9 compute from the Continuation Sheet; the retainage rate on line 5 drives every line.
B4: Amber cells are yours to fill in. Everything else calculates.
A6: FROM (CONTRACTOR — YOUR COMPANY) | D6: APPLICATION
A7: Company | D7: Application no.
A8: Address | D8: Period from
A9: Phone · email · license | D9: Period to
A11: TO (OWNER / GENERAL CONTRACTOR) | D11: PROJECT
A12: Company | D12: Project name
A13: Address | D13: Site address
A14: Contact | D14: Project no.
A16: CONTRACT | D16: CERTIFICATION
A17: Contract date | D17: Application date
A18: Contract for | D18: Submitted by
A19: Via architect / engineer | D19: Distribution to
A21: CONTRACTOR'S APPLICATION FOR PAYMENT
A22: The contractor applies for payment as shown below for work completed and materials presently stored through the period to date.
A23: 1. Original contract sum
A24: 2. Net change by change orders | D24: net of the change order summary below | F24: =F42
A25: 3. Contract sum to date | D25: Line 1 + 2 | F25: =F23+F24
A26: 4. Total completed and stored to date | D26: Continuation Sheet, column G total (D + E + F) | F26: ='Continuation Sheet'!G30
A27: 5. Retainage rate — edit; applies to every line | F27: 0.1
A28: a. Retainage on completed work (columns D + E) | F28: =ROUND(('Continuation Sheet'!D30+'Continuation Sheet'!E30)*F27,2)
A29: b. Retainage on stored material (column F) | F29: =ROUND('Continuation Sheet'!F30*F27,2)
A30: Total retainage (a + b) | F30: =F28+F29
A31: 6. Total earned less retainage | D31: Line 4 − 5 | F31: =F26-F30
A32: 7. Less previous certificates for payment | D32: enter line 6 of your previous application (0 on application no. 1)
A33: 8. Current payment due | D33: Line 6 − 7 | F33: =F31-F32
A34: 9. Balance to finish, including retainage | D34: Line 3 − 6 | F34: =F25-F31
A36: CHANGE ORDER SUMMARY
A37: CHANGE ORDERS APPROVED BY OWNER / GC | E37: ADDITIONS | F37: DEDUCTIONS
A38: Total approved in previous months
A39: Total approved this month
B40: list the CO numbers approved this period in the amber cell above
B41: Totals | E41: =SUM(E38:E39) | F41: =SUM(F38:F39)
A42: Net change by change orders (additions − deductions) → line 2 | F42: =E41-F41
A44: CONTRACTOR'S CERTIFICATION
A45: I certify that the work covered by this application has been completed as described on the continuation sheet, that amounts previously certified have been paid, and that the current payment shown is now due.
A47: CONTRACTOR | D47: CERTIFIED BY (OWNER / GENERAL CONTRACTOR)
A50: SIGNATURE | D50: SIGNATURE
...

Sheet Continuation Sheet
A1: Continuation Sheet | H1: Print: landscape, one page wide
A2: Schedule of values — one row per line item. Columns G to J calculate; the retainage rate comes from line 5 of the Pay Application sheet.
B4: Amber cells are yours to fill in. Everything else calculates. | F4: Application no. | G4: =IF('Pay Application'!E7="","",'Pay Application'!E7) | I4: Period to | J4: =IF('Pay Application'!E9="","",'Pay Application'!E9)
F5: Retainage rate | G5: ='Pay Application'!F27 | I5: Contract sum to date | J5: ='Pay Application'!F25
A7: A ITEM NO. | B7: B DESCRIPTION OF WORK | C7: C SCHEDULED VALUE | D7: D FROM PREVIOUS APPLICATIONS (D + E OF PRIOR) | E7: E THIS PERIOD | F7: F MATERIALS PRESENTLY STORED (NOT IN D OR E) | G7: G TOTAL COMPLETED & STORED TO DATE (D + E + F) | H7: H % (G ÷ C) | I7: I BALANCE TO FINISH (C − G) | J7: RETAINAGE (RATE × G)
G8: =IF($C8="","",D8+E8+F8) | H8: =IF(OR($C8="",$C8=0),"",G8/C8) | I8: =IF($C8="","",C8-G8) | J8: =IF($C8="","",ROUND(G8*'Pay Application'!$F$27,2))
G9: =IF($C9="","",D9+E9+F9) | H9: =IF(OR($C9="",$C9=0),"",G9/C9) | I9: =IF($C9="","",C9-G9) | J9: =IF($C9="","",ROUND(G9*'Pay Application'!$F$27,2))
G10: =IF($C10="","",D10+E10+F10) | H10: =IF(OR($C10="",$C10=0),"",G10/C10) | I10: =IF($C10="","",C10-G10) | J10: =IF($C10="","",ROUND(G10*'Pay Application'!$F$27,2))
G11: =IF($C11="","",D11+E11+F11) | H11: =IF(OR($C11="",$C11=0),"",G11/C11) | I11: =IF($C11="","",C11-G11) | J11: =IF($C11="","",ROUND(G11*'Pay Application'!$F$27,2))
G12: =IF($C12="","",D12+E12+F12) | H12: =IF(OR($C12="",$C12=0),"",G12/C12) | I12: =IF($C12="","",C12-G12) | J12: =IF($C12="","",ROUND(G12*'Pay Application'!$F$27,2))
G13: =IF($C13="","",D13+E13+F13) | H13: =IF(OR($C13="",$C13=0),"",G13/C13) | I13: =IF($C13="","",C13-G13) | J13: =IF($C13="","",ROUND(G13*'Pay Application'!$F$27,2))
G14: =IF($C14="","",D14+E14+F14) | H14: =IF(OR($C14="",$C14=0),"",G14/C14) | I14: =IF($C14="","",C14-G14) | J14: =IF($C14="","",ROUND(G14*'Pay Application'!$F$27,2))
G15: =IF($C15="","",D15+E15+F15) | H15: =IF(OR($C15="",$C15=0),"",G15/C15) | I15: =IF($C15="","",C15-G15) | J15: =IF($C15="","",ROUND(G15*'Pay Application'!$F$27,2))
G16: =IF($C16="","",D16+E16+F16) | H16: =IF(OR($C16="",$C16=0),"",G16/C16) | I16: =IF($C16="","",C16-G16) | J16: =IF($C16="","",ROUND(G16*'Pay Application'!$F$27,2))
G17: =IF($C17="","",D17+E17+F17) | H17: =IF(OR($C17="",$C17=0),"",G17/C17) | I17: =IF($C17="","",C17-G17) | J17: =IF($C17="","",ROUND(G17*'Pay Application'!$F$27,2))
G18: =IF($C18="","",D18+E18+F18) | H18: =IF(OR($C18="",$C18=0),"",G18/C18) | I18: =IF($C18="","",C18-G18) | J18: =IF($C18="","",ROUND(G18*'Pay Application'!$F$27,2))
G19: =IF($C19="","",D19+E19+F19) | H19: =IF(OR($C19="",$C19=0),"",G19/C19) | I19: =IF($C19="","",C19-G19) | J19: =IF($C19="","",ROUND(G19*'Pay Application'!$F$27,2))
... G29: =IF($C29="","",D29+E29+F29) | H29: =IF(OR($C29="",$C29=0),"",G29/C29) | I29: =IF($C29="","",C29-G29) | J29: =IF($C29="","",ROUND(G29*'Pay Application'!$F$27,2))
B30: Grand total | C30: =SUM(C8:C29) | D30: =SUM(D8:D29) | E30: =SUM(E8:E29) | F30: =SUM(F8:F29) | G30: =SUM(G8:G29) | H30: =IF(C30=0,"",G30/C30) | I30: =SUM(I8:I29) | J30: =SUM(J8:J29)
B31: Tie-out: column C total − contract sum to date (must be 0.00) | J31: =C30-'Pay Application'!F25
A33: Roll forward to the next application: once this application is approved, add each row's This Period (E) into From Previous Applications (D) as a value and clear E. Material that was stored (F) and has since been installed leaves F and is billed in E. Then change the application number and period dates on the Pay Application sheet, and enter this application's line 6 on the new line 7.
A35: Free template by BuildWorkPro — buildworkpro.com/templates. Column G is line 4 on the Pay Application; the retainage total is line 5. Change orders become new rows — use the CO number as the item number.

Sheet How to Use
A1: How to use the Pay Application Template
A4: 1. | B4: Fill in the header on the Pay Application sheet: your company, the owner or GC you bill, the project, and the application number and billing period. Amber cells are inputs.
A5: 2. | B5: Enter line 1, the original contract sum. Line 2 comes from the change order summary lower on the sheet — enter approved change orders as additions and deductions, split between previous months and this month.
A6: 3. | B6: Set the retainage rate on line 5 (10% is the default; 5% is common; some contracts step down after 50% complete). It drives the retainage column on the Continuation Sheet and lines 5a, 5b, 6 and 8.
A7: 4. | B7: On the Continuation Sheet, list your schedule of values — one row per line item, scheduled value in column C. The tie-out cell under the grand total must read 0.00: the scheduled values have to add up to the contract sum to date.
A8: 5. | B8: Each billing period enter This Period (E) and Materials Presently Stored (F) per row. Columns G to J, the grand total, and lines 4 to 9 calculate. Line 7 is the one number you type in from last period: its line 6.
A9: 6. | B9: Print both sheets (each fits one page), sign the certification, and send. Then roll forward: D = D + E, clear E, update F, bump the application number, and enter last period’s line 6 on line 7.
B11: TIPS FROM THE FIELD
A12: • | B12: Keep the item numbers identical to your schedule of values and add approved change orders as new rows with the CO number as the item number — the GC traces every dollar back to a signed document.
A13: • | B13: Stored materials need backup: invoices, a bill of sale or delivery ticket, and proof of insurance on the stored items. Bill them in F only until they are installed, then move them to E.
A14: • | B14: Line 8 is what you get paid. If the GC certifies a different amount, the difference is what to reconcile before the next application — do not let it drift.
A16: In BuildWorkPro the schedule of values prefills from your accepted bid and approved change orders, previous applications lock and carry forward automatically, retainage is a field on every pay app, and the PDF emails to your GC from the app.
B17: https://buildworkpro.com/features/pay-applications/
A19: Free template by BuildWorkPro — https://buildworkpro.com/templates/. Free to use and share for your own business. Not legal, accounting or engineering advice.
